#VRML_SIM R2023b utf8

PROTO DiffDriveRobotWithEyes [
  field SFVec3f    translation  0 0 0
  field SFRotation rotation     0 1 0 3.14
  field SFFloat    bodyMass     1
]
{
Robot {
  translation 0 0 0.045
  rotation 0 -1 0 0.00159123
  children [
    DEF BodyShapeWithTransform Pose {
      children [
        DEF Body Shape {
          appearance PBRAppearance {
            baseColor 1 0 0
            roughness 1
            metalness 0
          }
          geometry Cylinder {
            height 0.08
            radius 0.045
          }
        }
      ]
    }
    DEF wheel_joint HingeJoint {
      jointParameters HingeJointParameters {
        anchor -0.045 0.025 0
      }
      device [
        RotationalMotor {
          name "motor_1"
        }
      ]
      endPoint Solid {
        translation -0.05 0 -0.02
        rotation 0 1 0 1.5236003061004253
        children [
          DEF shape_wheel Shape {
            appearance PBRAppearance {
              baseColor 0 0 1
              roughness 1
              metalness 0
            }
            geometry Cylinder {
              height 0.01
              radius 0.025
            }
          }
        ]
        boundingObject USE shape_wheel
        physics DEF wheel_physics Physics {
        }
      }
    }
    DEF wheel_joint HingeJoint {
      jointParameters HingeJointParameters {
        anchor 0.045 0.025 0
      }
      device [
        RotationalMotor {
          name "motor_2"
        }
      ]
      endPoint Solid {
        translation 0.05 0 -0.02
        rotation 0 1 0 1.52
        children [
          DEF shape_wheel Shape {
            appearance PBRAppearance {
              baseColor 0 0 1
              roughness 1
              metalness 0
            }
            geometry Cylinder {
              height 0.01
              radius 0.025
            }
          }
        ]
        name "solid(1)"
        boundingObject USE shape_wheel
        physics USE wheel_physics
      }
    }
    DEF eye_solid Solid {
      translation 0.015 0.045 0.025
      children [
        Shape {
          appearance PBRAppearance {
            baseColor 0 0 1
            roughness 1
            metalness 0
          }
          geometry Box {
            size 0.005 0.005 0.005
          }
        }
      ]
      name "eye_left"
    }
    DEF eye_solid Solid {
      translation -0.015 0.045 0.025
      children [
        Shape {
          appearance PBRAppearance {
            baseColor 0 0 1
            roughness 1
            metalness 0
          }
          geometry Box {
            size 0.005 0.005 0.005
          }
        }
      ]
      name "eye_right"
    }
    DEF lidar Solid {
      translation 0 0 0.042
      children [
        Shape {
          appearance PBRAppearance {
            baseColor 0 0 1
            roughness 1
            metalness 0
          }
          geometry Box {
            size 0.005 0.005 0.005
          }
        }
      ]
      name "lidar"
    }
  ]
  boundingObject USE BodyShapeWithTransform
  physics Physics {
    density -1
    mass 1
  }
}
}
