#VRML_SIM R2023b utf8

EXTERNPROTO "https://raw.githubusercontent.com/cyberbotics/webots/R2023b/projects/objects/backgrounds/protos/TexturedBackground.proto"
EXTERNPROTO "https://raw.githubusercontent.com/cyberbotics/webots/R2023b/projects/appearances/protos/Parquetry.proto"
EXTERNPROTO "https://raw.githubusercontent.com/cyberbotics/webots/R2023b/projects/objects/apartment_structure/protos/Wall.proto"
EXTERNPROTO "https://raw.githubusercontent.com/cyberbotics/webots/R2023b/projects/objects/apartment_structure/protos/Window.proto"
EXTERNPROTO "https://raw.githubusercontent.com/cyberbotics/webots/R2023b/projects/appearances/protos/PaintedWood.proto"
EXTERNPROTO "https://raw.githubusercontent.com/cyberbotics/webots/R2023b/projects/objects/apartment_structure/protos/Door.proto"
EXTERNPROTO "https://raw.githubusercontent.com/cyberbotics/webots/R2023b/projects/objects/apartment_structure/protos/DoorLever.proto"
EXTERNPROTO "https://raw.githubusercontent.com/cyberbotics/webots/R2023b/projects/objects/lights/protos/CeilingLight.proto"
EXTERNPROTO "https://raw.githubusercontent.com/cyberbotics/webots/R2023b/projects/objects/lights/protos/FloorLight.proto"
EXTERNPROTO "https://raw.githubusercontent.com/cyberbotics/webots/R2023b/projects/objects/kitchen/fridge/protos/Fridge.proto"
EXTERNPROTO "https://raw.githubusercontent.com/cyberbotics/webots/R2023b/projects/objects/cabinet/protos/Cabinet.proto"
EXTERNPROTO "https://raw.githubusercontent.com/cyberbotics/webots/R2023b/projects/objects/cabinet/protos/CabinetHandle.proto"
EXTERNPROTO "https://raw.githubusercontent.com/cyberbotics/webots/R2023b/projects/objects/kitchen/oven/protos/Oven.proto"
EXTERNPROTO "https://raw.githubusercontent.com/cyberbotics/webots/R2023b/projects/objects/kitchen/components/protos/Worktop.proto"
EXTERNPROTO "https://raw.githubusercontent.com/cyberbotics/webots/R2023b/projects/objects/kitchen/components/protos/Sink.proto"
EXTERNPROTO "https://raw.githubusercontent.com/cyberbotics/webots/R2023b/projects/objects/kitchen/components/protos/HotPlate.proto"
EXTERNPROTO "https://raw.githubusercontent.com/cyberbotics/webots/R2023b/projects/objects/drinks/protos/Can.proto"
EXTERNPROTO "https://raw.githubusercontent.com/cyberbotics/webots/R2023b/projects/objects/tables/protos/Table.proto"
EXTERNPROTO "https://raw.githubusercontent.com/cyberbotics/webots/R2023b/projects/objects/chairs/protos/Chair.proto"
EXTERNPROTO "https://raw.githubusercontent.com/cyberbotics/webots/R2023b/projects/objects/fruits/protos/FruitBowl.proto"
EXTERNPROTO "https://raw.githubusercontent.com/cyberbotics/webots/R2023b/projects/objects/fruits/protos/Orange.proto"
EXTERNPROTO "https://raw.githubusercontent.com/cyberbotics/webots/R2023b/projects/objects/fruits/protos/Apple.proto"
EXTERNPROTO "https://raw.githubusercontent.com/cyberbotics/webots/R2023b/projects/objects/tables/protos/Desk.proto"
EXTERNPROTO "https://raw.githubusercontent.com/cyberbotics/webots/R2023b/projects/objects/chairs/protos/WoodenChair.proto"
EXTERNPROTO "https://raw.githubusercontent.com/cyberbotics/webots/R2023b/projects/objects/school_furniture/protos/Book.proto"
EXTERNPROTO "https://raw.githubusercontent.com/cyberbotics/webots/R2023b/projects/objects/living_room_furniture/protos/Armchair.proto"
EXTERNPROTO "https://raw.githubusercontent.com/cyberbotics/webots/R2023b/projects/objects/living_room_furniture/protos/Sofa.proto"
EXTERNPROTO "https://raw.githubusercontent.com/cyberbotics/webots/R2023b/projects/objects/living_room_furniture/protos/Carpet.proto"
EXTERNPROTO "https://raw.githubusercontent.com/cyberbotics/webots/R2023b/projects/objects/plants/protos/BunchOfSunFlowers.proto"
EXTERNPROTO "https://raw.githubusercontent.com/cyberbotics/webots/R2023b/projects/objects/plants/protos/PottedTree.proto"
EXTERNPROTO "https://raw.githubusercontent.com/cyberbotics/webots/R2023b/projects/objects/paintings/protos/PortraitPainting.proto"
EXTERNPROTO "https://raw.githubusercontent.com/cyberbotics/webots/R2023b/projects/objects/paintings/protos/LandscapePainting.proto"
EXTERNPROTO "https://raw.githubusercontent.com/cyberbotics/webots/R2023b/projects/objects/television/protos/Television.proto"

WorldInfo {
  info [
    "Sample of how the indoor objects can be placed"
  ]
  basicTimeStep 16
}
Viewpoint {
  orientation -0.3918554615750794 0.5959552007297619 0.7009184659836908 1.5069382658138577
  position -4.262993362833827 -7.286777255036836 9.22426678744976
  exposure 0.5
}
TexturedBackground {
  texture "empty_office"
  skybox FALSE
  skyColor [
    0.2 0.2 0.2
  ]
}
DEF FLOOR Solid {
  translation -4.95 -3.3 0
  children [
    Shape {
      appearance Parquetry {
        textureTransform TextureTransform {
          scale 6 9
        }
      }
      geometry DEF FLOOR_PLANE Plane {
        size 9.9 6.6
      }
    }
  ]
  name "floor"
  boundingObject USE FLOOR_PLANE
  locked TRUE
}
Robot {
  translation -2.2532 -1.62491 0.3
  rotation 0 0 1 -2.881385307179586
  children [
    Display {
      name "obj_display"
      width 640
      height 640
    }
    Display {
      width 640
      height 640
    }
    DEF BodyShapeWithTransform Pose {
      children [
        DEF Body Shape {
          appearance PBRAppearance {
            baseColor 0.3 0.3 0.3
            roughness 1
            metalness 0
          }
          geometry Cylinder {
            height 0.5
            radius 0.2
          }
        }
      ]
    }
    Solid {
      translation 0 -0.25 -0.25
      children [
        Shape {
          appearance Appearance {
            material Material {
            }
          }
          geometry DEF sphere Sphere {
            radius 0.05
          }
        }
      ]
      name "rear support"
      boundingObject USE sphere
      physics Physics {
        density -1
        mass 0.01
      }
    }
    Solid {
      translation 0 0.25 -0.25
      children [
        Shape {
          appearance Appearance {
            material Material {
            }
          }
          geometry DEF sphere Sphere {
            radius 0.05
          }
        }
      ]
      name "front support"
      boundingObject USE sphere
      physics Physics {
        density -1
        mass 0.01
      }
    }
    DEF wheel_joint_l HingeJoint {
      jointParameters HingeJointParameters {
        position 5.184067726082308
        anchor 0 0 -0.2
      }
      device [
        RotationalMotor {
          name "motor_l1"
        }
      ]
      endPoint Solid {
        translation -0.25 0 -0.2
        rotation 0.45962221983921875 -0.7573441520333398 0.46387201943097417 4.4291140464425105
        children [
          DEF shape_wheel Shape {
            appearance PBRAppearance {
              baseColor 0.1 0.1 0.1
              roughness 1
              metalness 0
            }
            geometry Cylinder {
              height 0.1
              radius 0.1
            }
          }
        ]
        name "motor_l1_solid"
        boundingObject USE shape_wheel
        physics DEF wheel_physics Physics {
          density -1
          mass 0.01
        }
      }
    }
    DEF wheel_joint_r HingeJoint {
      jointParameters HingeJointParameters {
        position -5.183968885302215
        anchor 0.25 0 -0.2
      }
      device [
        RotationalMotor {
          name "motor_r1"
        }
      ]
      endPoint Solid {
        translation 0.25 0 -0.2
        rotation -0.45965146961597936 -0.757308317649633 -0.4639015396596058 4.429068615578198
        children [
          DEF shape_wheel Shape {
            appearance PBRAppearance {
              baseColor 0.1 0.1 0.1
              roughness 1
              metalness 0
            }
            geometry Cylinder {
              height 0.1
              radius 0.1
            }
          }
        ]
        name "motor_r1_solid"
        boundingObject USE shape_wheel
        physics USE wheel_physics
        locked TRUE
      }
    }
    Lidar {
      translation 0 0.2 0.25
      rotation 0 0 1 1.57
      name "lidar_sensor"
      horizontalResolution 720
      fieldOfView 3.14
      verticalFieldOfView 1.57
      numberOfLayers 1
      near 0.0001
      minRange 0.0001
      maxRange 20
      defaultFrequency 25
    }
    InertialUnit {
      translation 0 0 0.2
      name "imu"
    }
    Camera {
      translation 0 0.2 0.25
      rotation 0 0 1 1.58
      width 2048
      height 2048
    }
    GPS {
    }
  ]
  boundingObject USE BodyShapeWithTransform
  physics Physics {
    density -1
    mass 0.01
  }
  controller "<extern>"
}
DEF ROOF Solid {
  translation -4.95 -3.3 2.3999
  rotation 1 0 0 3.14159
  children [
    Shape {
      appearance PBRAppearance {
        baseColor 0.8 0.8 0.8
        baseColorMap ImageTexture {
          url [
            "https://raw.githubusercontent.com/cyberbotics/webots/R2023b/projects/default/worlds/textures/roughcast.jpg"
          ]
        }
        roughness 0.5
        metalness 0
        textureTransform TextureTransform {
          scale 8 8
        }
      }
      geometry USE FLOOR_PLANE
    }
  ]
  name "roof"
  boundingObject USE FLOOR_PLANE
  locked TRUE
}
Wall {
  translation 0 -0.65 0
  name "wall 1"
  size 0.3 1 2.4
}
Window {
  translation 0 -1.65 0
  name "window 1"
  size 0.3 1 2.4
  frameAppearance PaintedWood {
    colorOverride 0.13333333333333333 0.13333333333333333 0.13333333333333333
  }
}
Wall {
  translation 0 -4.3 0
  name "wall 2"
  size 0.3 4.3 2.4
}
Wall {
  translation -9.9 -2.3 0
  name "wall 3"
  size 0.3 4.3 2.4
}
Wall {
  translation -9.9 -5.95 0
  name "wall 4"
  size 0.3 1 2.4
}
Door {
  translation -9.9 -4.95 0
  name "door 1"
  size 0.3 1 2.4
  canBeOpen FALSE
  frameAppearance PaintedWood {
    colorOverride 0.13333333333333333 0.13333333333333333 0.13333333333333333
  }
  doorHandle DoorLever {
    hasStaticParent TRUE
  }
}
Wall {
  translation -3.8 0 0
  rotation 0 0 1 1.5708
  name "wall 5"
  size 0.3 7.9 2.4
}
Wall {
  translation -9.4 0 0
  rotation 0 0 1 1.5708
  name "wall 6"
  size 0.3 1.3 2.4
}
Window {
  translation -8.25 0 0
  rotation 0 0 1 1.5708
  name "window 2"
  size 0.3 1 2.4
  frameAppearance PaintedWood {
    colorOverride 0.13333333333333333 0.13333333333333333 0.13333333333333333
  }
}
Wall {
  translation -9.4 -6.6 0
  rotation 0 0 1 1.5708
  name "wall 7"
  size 0.3 1.3 2.4
}
Door {
  translation -8.25 -6.6 0
  rotation 0 0 1 1.5708
  name "door 2"
  size 0.3 1 2.4
  canBeOpen FALSE
  frameAppearance PaintedWood {
    colorOverride 0.13333333333333333 0.13333333333333333 0.13333333333333333
  }
  doorHandle DoorLever {
    rotation -0.0012868889344011497 0.9999991719580925 0 0
    hasStaticParent TRUE
  }
}
Wall {
  translation -3.8 -6.6 0
  rotation 0 0 1 1.5708
  name "wall 8"
  size 0.3 7.9 2.4
}
Wall {
  translation -3.3 -1.8 0
  name "wall 9"
  size 0.3 3.3 2.4
}
CeilingLight {
  translation -1.3341 -2.4706 2.4
  name "ceiling light 1"
  pointLightIntensity 5
}
CeilingLight {
  translation -7.1011 -2.4432 2.4
  name "ceiling light 2"
  pointLightIntensity 8
}
FloorLight {
  translation -4.0043 -0.7456 0
  pointLightIntensity 2
}
Fridge {
  translation -0.52 -0.5 0
  rotation 0 0 1 -1.5707953071795862
  mainColor 0.6666666666666666 0 0
}
Cabinet {
  translation -1.31 -0.15 0
  rotation 0 0 -1 1.5708
  name "cabinet 1"
  depth 0.68
  outerThickness 0.02
  rowsHeights [
    0.22, 0.21, 0.21
  ]
  columnsWidths [
    0.42, 0.42
  ]
  layout [
    "Drawer (1, 1, 1, 1, 1.5)"
    "Drawer (1, 2, 1, 1, 1.5)"
    "Drawer (1, 3, 1, 1, 1.5)"
    "Shelf  (1, 2, 2, 0)"
    "Shelf  (1, 3, 2, 0)"
    "Shelf (1, 1, 0, 3)"
  ]
  handle CabinetHandle {
    handleLength 0.09
    handleRadius 0.008
  }
  primaryAppearance PaintedWood {
    colorOverride 0.13333333333333333 0.13333333333333333 0.13333333333333333
  }
  secondaryAppearance PaintedWood {
    colorOverride 0.13333333333333333 0.13333333333333333 0.13333333333333333
  }
}
Cabinet {
  translation -1.31 -0.15 1.12
  rotation 0 0 1 -1.5707953071795862
  name "cabinet 2"
  outerThickness 0.02
  rowsHeights [
    0.22, 0.21, 0.21
  ]
  columnsWidths [
    0.42, 0.42
  ]
  layout [
    "RightSidedDoor (1, 1, 1, 3, 1.5)"
    "LeftSidedDoor (2, 1, 1, 3, 1.5)"
    "Shelf  (1, 2, 2, 0)"
    "Shelf  (1, 3, 2, 0)"
    "Shelf (1, 1, 0, 3)"
  ]
  handle CabinetHandle {
    translation 0 -0.2 0
    handleLength 0.09
    handleRadius 0.008
  }
  primaryAppearance PaintedWood {
    colorOverride 0.13333333333333333 0.13333333333333333 0.13333333333333333
  }
  secondaryAppearance PaintedWood {
    colorOverride 0.13333333333333333 0.13333333333333333 0.13333333333333333
  }
}
Cabinet {
  translation -2.19 -0.15 0
  rotation 0 0 1 -1.5707953071795862
  name "cabinet 3"
  depth 0.68
  outerThickness 0.02
  rowsHeights [
    0.22, 0.21, 0.21
  ]
  columnsWidths [
    0.42, 0.42
  ]
  layout [
    "LeftSidedDoor (2, 1, 1, 3, 1.5)"
    "Shelf  (1, 2, 2, 0)"
    "Shelf  (1, 3, 2, 0)"
    "Shelf (1, 1, 0, 3)"
  ]
  handle CabinetHandle {
    translation 0 0.2 0
    handleLength 0.09
    handleRadius 0.008
  }
  primaryAppearance PaintedWood {
    colorOverride 0.13333333333333333 0.13333333333333333 0.13333333333333333
  }
  secondaryAppearance PaintedWood {
    colorOverride 0.13333333333333333 0.13333333333333333 0.13333333333333333
  }
}
Oven {
  translation -2.85 -0.58 0
  rotation 0 0 1 -1.5707953071795862
}
Worktop {
  translation -1.31 -0.5 0.71
  rotation 1 0 0 1.5708
  name "worktop 1"
  size 0.88 0.06 0.7
}
Worktop {
  translation -1.97 -0.807 0.71
  rotation 1 0 0 1.5708
  name "worktop 2"
  size 0.44 0.06 0.086
}
Worktop {
  translation -1.97 -0.272 0.71
  rotation 1 0 0 1.5708
  name "worktop 3"
  size 0.44 0.06 0.244
}
Worktop {
  translation -2.63 -0.5 0.71
  rotation 1 0 0 1.5708
  name "worktop 4"
  size 0.88 0.06 0.7
}
Sink {
  translation -1.97 -0.48 0.715
  rotation 0 0 1 -1.5707953071795862
}
HotPlate {
  translation -2.85 -0.5 0.71
  rotation 0 0 1 -1.5707953071795862
}
Can {
  translation -0.5663 -0.6328 0.8410656650333487
  rotation -0.78751225520998 0.6147676314864998 0.043418972472530994 1.6688732453130798e-16
  name "can 1"
}
Table {
  translation -1.0743 -4.9444 0
  rotation 0 0 1 1.5708
  name "table(1)"
}
Chair {
  translation -1.4606 -5.4128 -0.0022445280266748524
  rotation -1.6881941931823624e-17 3.630097011141964e-17 1 1.5708000000000002
  name "chair 1"
  color 0.13333333333333333 0.13333333333333333 0.13333333333333333
  physics Physics {
    centerOfMass [
      0 0 0.45
    ]
  }
}
Chair {
  translation -0.6425 -4.4443 -0.0022445280266750745
  rotation 3.0375322154014935e-18 6.990485847724331e-18 -0.9999999999999999 1.5707953071795862
  name "chair 2"
  color 0.13333333333333333 0.13333333333333333 0.13333333333333333
  physics Physics {
    centerOfMass [
      0 0 0.45
    ]
  }
}
Chair {
  translation -1.3943 -4.4875 -0.0022445280266750745
  rotation -1.811227898864162e-18 -6.902775727951038e-18 -0.9999999999999999 1.5707953071795862
  name "chair 3"
  color 0.13333333333333333 0.13333333333333333 0.13333333333333333
  physics Physics {
    centerOfMass [
      0 0 0.45
    ]
  }
}
Chair {
  translation -0.7069 -5.3809 -0.0022445280266748524
  rotation 5.958296969637062e-17 -5.625764600671178e-17 1 1.5708000000000002
  name "chair 4"
  color 0.13333333333333333 0.13333333333333333 0.13333333333333333
  physics Physics {
    centerOfMass [
      0 0 0.45
    ]
  }
}
FruitBowl {
  translation -0.7155000195898064 -4.880599991995642 0.7397841799998895
  rotation 0.0001266334981751839 -4.085531288461245e-05 0.9999999911474002 0.9446150066981543
  color 0.6666666666666666 0 0
}
Orange {
  translation -0.7836765467991426 -4.901958216769091 0.7996652513609198
  rotation 0.9710632338997126 -0.23851088656162436 0.012196424058704068 0.6690777871044818
}
Orange {
  translation -0.725071050113342 -4.820931121615838 0.7996737544295511
  rotation 0.3663780344038409 -0.3690169887013167 0.8541625126146606 1.340080132207693
  name "orange 2"
}
Apple {
  translation -0.7026493918918523 -4.960563657668556 0.7996566687773389
  rotation -0.09377197217133502 0.08814617132129651 0.9916839565690752 1.748810981896224
}
Apple {
  translation -0.6440435239978881 -4.87953602402084 0.7996652303192786
  rotation -0.5571458704758391 -0.49352300407681116 0.6678499258506503 0.5078138092633508
  name "apple 2"
}
Desk {
  translation -5.125 -0.5126 0
  rotation 0 0 1 1.5708
}
WoodenChair {
  translation -5.14999999992856 -0.9000000307053436 -0.000827215908927259
  rotation -3.0709760824301144e-05 3.056719293986731e-05 0.9999999990612788 1.5708000009467942
  physics Physics {
    centerOfMass [
      0 0 0.45
    ]
  }
}
Book {
  translation -4.69759937683887 -0.5922002817005871 0.7198822799924054
  rotation 0.6215345943979392 0.4768867163404712 0.6215092981964083 -2.2515380803878298
  name "book(1)"
}
Table {
  translation -7.163 -2.5554 0.0199
  size 0.8 1.2 0.53
}
Armchair {
  translation -5.8922 -3.8267 0
  rotation 0 0 1 2.30591
  color 0.13333333333333333 0.13333333333333333 0.13333333333333333
}
Sofa {
  translation -7.0533 -0.8042 0
  rotation 2.3464099999870814e-06 -2.3464099999870814e-06 0.9999999999944944 -1.5707953071795862
  color 0.13333333333333333 0.13333333333333333 0.13333333333333333
}
Sofa {
  translation -8.9573 -2.4973 0
  name "sofa 2"
  color 0.13333333333333333 0.13333333333333333 0.13333333333333333
}
Carpet {
  translation -7.1422 -2.5507 -0.0151
  rotation 0 0 1 -1.5707953071795862
  color 0.13725490196078433 0.13725490196078433 0.13725490196078433
}
BunchOfSunFlowers {
  translation -9.0598 -3.9144 0
}
Book {
  translation -4.69169776553867 -0.5961009992996008 0.7398522018620461
  rotation 0.6786317432294477 0.28105842782508345 0.6785758006515213 -2.5935077960335104
}
Can {
  translation -7.226322463356063 -2.7419125248907807 0.610977470056352
  rotation 0.00030730597184107703 -0.00013515108874581248 -0.9999999436486098 1.294910232429207
  name "can 2"
}
Can {
  translation -7.35 -2.7233 0.6109656650333487
  rotation 0.11660016651015098 0.9827728320141547 0.14339442745338238 5.090352345379699e-17
  name "can 3"
}
Can {
  translation -7.2069 -2.8744 0.6109656650333487
  rotation 1.0049229347803837e-16 1.1098081917259707e-17 1 1.32183
  name "can 4"
}
Cabinet {
  translation -3.4681 -6.4326 0
  rotation 0 0 -1 -1.5707953071795862
  name "cabinet 4"
  depth 0.4
  outerThickness 0.02
  rowsHeights [
    0.52, 0.44, 0.44, 0.44, 0.44
  ]
  columnsWidths [
    0.96
  ]
  layout [
    "Shelf  (1, 2, 1, 0)"
    "Shelf  (1, 3, 1, 0)"
    "Shelf  (1, 4, 1, 0)"
    "Shelf  (1, 5, 1, 0)"
  ]
  primaryAppearance PaintedWood {
    colorOverride 0.13333333333333333 0.13333333333333333 0.13333333333333333
  }
  secondaryAppearance PaintedWood {
    colorOverride 0.13333333333333333 0.13333333333333333 0.13333333333333333
  }
}
Book {
  translation -3.022317853641833 -6.1509000010808625 1.5292446000967774
  rotation 0.12394526734832674 7.060923597280086e-08 0.992289056022461 -3.1415909031869913
  name "book 2"
}
Book {
  translation -3.044710150668092 -6.157600004543027 1.5289667636657829
  rotation 0.1322874276506315 -1.037748799227425e-07 0.991211398484485 -3.1415896991798133
  name "book 3"
}
Book {
  translation -3.0668171838517297 -6.164199986784805 1.5287671726922918
  rotation 0.13881202264670234 2.0527795588516279e-07 0.9903187478628733 3.141590820994328
  name "book 4"
}
Book {
  translation -3.0912055034950243 -6.158199956267025 1.528160525843211
  rotation 0.1552046568313823 4.6553694829428595e-07 0.9878823383873386 3.141588856381992
  name "book 5"
}
Book {
  translation -3.11390221571618 -6.162299940777126 1.527790316380928
  rotation 0.16263139178682645 3.239601253795593e-07 0.9866868958313851 3.141590438390098
  name "book 6"
}
PottedTree {
  translation -4.517 -6.0805 0
}
PortraitPainting {
  translation -9.73 -2.47 1.5999
}
LandscapePainting {
  translation -0.1845 -4.9252 1.6286
  rotation 0 0 1 3.14159
}
Television {
  translation -3.4329 -2.1547 1.5596
  rotation 0 0 1 3.14159
}
