#VRML_SIM R2023b utf8

EXTERNPROTO "https://raw.githubusercontent.com/cyberbotics/webots/R2023b/projects/objects/backgrounds/protos/TexturedBackground.proto"
EXTERNPROTO "https://raw.githubusercontent.com/cyberbotics/webots/R2023b/projects/objects/backgrounds/protos/TexturedBackgroundLight.proto"
EXTERNPROTO "https://raw.githubusercontent.com/cyberbotics/webots/R2023b/projects/objects/floors/protos/RectangleArena.proto"
EXTERNPROTO "https://raw.githubusercontent.com/cyberbotics/webots/R2023b/projects/appearances/protos/Parquetry.proto"
EXTERNPROTO "https://raw.githubusercontent.com/cyberbotics/webots/R2023b/projects/appearances/protos/BrushedAluminium.proto"


WorldInfo {
}
Viewpoint {
  orientation 0 -1 0 5.1
  position -14 -2 37
  followType "None"
}
TexturedBackground {
  texture "entrance_hall"
  skybox FALSE
  skyColor [
    0.4 0.4 0.4
  ]
}
TexturedBackgroundLight {
  texture "entrance_hall"
}
Robot {
  translation 0 0 0.3
  rotation 0 0 1 3.14
  children [
    DEF BodyShapeWithTransform Pose {
      translation 0 0 0.4
      children [
        DEF Body Shape {
          appearance PBRAppearance {
            baseColor 0.3 0.3 0.3
            roughness 1
            metalness 0
          }
          geometry Cylinder {
            height 1.8
            radius 0.45
          }
        }
      ]
    }
    Solid {
      translation 0 -0.5 -0.477
      children [
        Shape {
          appearance Appearance {
            material Material {
              emissiveColor 0 0 0
            }
          }
          geometry Sphere {
            radius 0.1
          }
        }
      ]
      name "rear support"
      boundingObject Sphere {
        radius 0.1
      }
      physics Physics {
        density -1
        mass 0.01
      }
    }
    Solid {
      translation 0 0.5 -0.477
      children [
        Shape {
          appearance Appearance {
            material Material {
              emissiveColor 0 0 0
            }
          }
          geometry Sphere {
            radius 0.1
          }
        }
      ]
      name "front support"
      boundingObject Sphere {
        radius 0.1
      }
      physics Physics {
        density -1
        mass 0.01
      }
    }
    DEF wheel_joint HingeJoint {
      jointParameters HingeJointParameters {
        position 5.184067726082308
        anchor -0.5 0 -0.35
      }
      device [
        RotationalMotor {
          name "motor_l1"
        }
      ]
      endPoint Solid {
        translation -0.5 0 -0.35
        rotation 0.45962221983921875 -0.7573441520333398 0.46387201943097417 4.4291140464425105
        children [
          DEF shape_wheel Shape {
            appearance PBRAppearance {
              baseColor 0.1 0.1 0.1
              roughness 1
              metalness 0
            }
            geometry Cylinder {
              height 0.1
              radius 0.25
            }
          }
        ]
        name "motor_l1_solid"
        boundingObject USE shape_wheel
        physics DEF wheel_physics Physics {
          density -1
          mass 0.01
        }
      }
    }
    DEF wheel_joint HingeJoint {
      jointParameters HingeJointParameters {
        position -5.183968885302215
        anchor 0.5 0 -0.3
      }
      device [
        RotationalMotor {
          name "motor_r1"
        }
      ]
      endPoint Solid {
        translation 0.5 0 -0.3
        rotation -0.45965146961597936 -0.7573083176496329 -0.4639015396596058 4.429068615578198
        children [
          DEF shape_wheel Shape {
            appearance PBRAppearance {
              baseColor 0.1 0.1 0.1
              roughness 1
              metalness 0
            }
            geometry Cylinder {
              height 0.1
              radius 0.25
            }
          }
        ]
        name "motor_r1_solid"
        boundingObject USE shape_wheel
        physics USE wheel_physics
      }
    }
    Lidar {
      translation 0 0.4 1.15
      rotation 0 0 1 1.57
      name "lidar_sensor"
      horizontalResolution 360
      fieldOfView 3.14
      verticalFieldOfView 1.57
      numberOfLayers 1
      near 1e-04
      minRange 1e-04
      maxRange 10
    }
    InertialUnit {
      translation 0 0 0.2
      name "imu"
    }
    Camera {
      translation 0 0.4 0.9
      rotation 0 0 1 1.58
      width 1000
      height 1000
    }
    GPS {
    }
  ]
  boundingObject USE BodyShapeWithTransform
  physics Physics {
    density -1
    mass 0.01
  }
  controller "<extern>"
}
Solid {
  translation 4.2 0 0
  children [
    CadShape {
      url [
        "map.dae"
      ]
    }
  ]
  name "map"
  boundingObject Mesh {
    url [
      "map.dae"
    ]
  }
}
RectangleArena {
  translation 1 -5 -0.4
  name "floor"
  floorSize 22 22
  floorTileSize 10 10
  floorAppearance Parquetry {
    type "light strip"
    IBLStrength 0.6
  }
  wallThickness 0.5
  wallHeight 3
  wallAppearance BrushedAluminium {
    colorOverride 0.3 0.3 0.3
    IBLStrength 0.2
  }
}